Backup failed for Site frappe.test. Database or site_config.json may be corrupted
Traceback with variables (most recent call last):
  File "apps/frappe/frappe/commands/site.py", line 871, in backup
    odb = scheduled_backup(
      context = CliCtxObj(sites=['frappe.test', 'project-management'], force=False, profile=False, verbose=True)
      with_files = False
      backup_path = None
      backup_path_db = None
      backup_path_files = None
      backup_path_private_files = None
      backup_path_conf = None
      ignore_backup_conf = False
      verbose = True
      compress = False
      include = ''
      exclude = ''
      old_backup_metadata = False
      scheduled_backup = <function scheduled_backup at 0x107c9d360>
      exit_code = 0
      rollback_callback = None
      site = 'frappe.test'
  File "apps/frappe/frappe/utils/backups.py", line 577, in scheduled_backup
    return new_backup(
      older_than = 6
      ignore_files = True
      backup_path = None
      backup_path_db = None
      backup_path_files = None
      backup_path_private_files = None
      backup_path_conf = None
      ignore_conf = False
      include_doctypes = ''
      exclude_doctypes = ''
      compress = False
      force = True
      verbose = True
      old_backup_metadata = False
      rollback_callback = <frappe.utils.CallbackManager object at 0x107ea9a50>
  File "apps/frappe/frappe/utils/backups.py", line 635, in new_backup
    odb.get_backup(older_than, ignore_files, force=force)
      older_than = 6
      ignore_files = True
      backup_path = None
      backup_path_db = None
      backup_path_files = None
      backup_path_private_files = None
      backup_path_conf = None
      ignore_conf = False
      include_doctypes = ''
      exclude_doctypes = ''
      compress = False
      force = True
      verbose = True
      old_backup_metadata = False
      rollback_callback = <frappe.utils.CallbackManager object at 0x107ea9a50>
      odb = <frappe.utils.backups.BackupGenerator object at 0x107ea9ae0>
  File "apps/frappe/frappe/utils/backups.py", line 191, in get_backup
    self.delete_if_step_fails(self.take_dump, self.backup_path_db)
      self = <frappe.utils.backups.BackupGenerator object at 0x107ea9ae0>
      older_than = 6
      ignore_files = True
      force = True
      last_db = False
      last_file = False
      last_private_file = False
      site_config_backup_path = False
  File "apps/frappe/frappe/utils/backups.py", line 516, in delete_if_step_fails
    raise e
      self = <frappe.utils.backups.BackupGenerator object at 0x107ea9ae0>
      step = <bound method BackupGenerator.take_dump of <frappe.utils.backups.BackupGenerator object at 0x107ea9ae0>>
      paths = ('./frappe.test/private/backups/20250209_060004-frappe_test-database.sql.gz',)
      path = './frappe.test/private/backups/20250209_060004-frappe_test-database.sql.gz'
  File "apps/frappe/frappe/utils/backups.py", line 511, in delete_if_step_fails
    step()
      self = <frappe.utils.backups.BackupGenerator object at 0x107ea9ae0>
      step = <bound method BackupGenerator.take_dump of <frappe.utils.backups.BackupGenerator object at 0x107ea9ae0>>
      paths = ('./frappe.test/private/backups/20250209_060004-frappe_test-database.sql.gz',)
      path = './frappe.test/private/backups/20250209_060004-frappe_test-database.sql.gz'
  File "apps/frappe/frappe/utils/backups.py", line 453, in take_dump
    frappe.throw(
      shlex = <module 'shlex' from '/Library/Frameworks/Python.framework/Versions/3.10/lib/python3.10/shlex.py'>
      frappe = <module 'frappe' from 'apps/frappe/frappe/__init__.py'>
      get_app_branch = <function get_app_branch at 0x107ed6710>
      gzip_exc = '/usr/bin/gzip'
      database_header_content = ['begin frappe metadata', '[frappe]', 'version = 16.0.0-dev', 'branch = develop', 'end frappe metadata', '']
      generated_header = '-- begin frappe metadata\n-- [frappe]\n-- version = 16.0.0-dev\n-- branch = develop\n-- end frappe metadata\n-- \n'
      f = <_io.TextIOWrapper name='./frappe.test/private/backups/20250209_060004-frappe_test-database.sql.gz' encoding='UTF-8'>
      cmd = []
      extra = []
      get_command = <function get_command at 0x107ce2830>
      bin = None
      args = ['--user=_749103ee63621ec5', '--host=127.0.0.1', '--port=3306', '--password=64NOp3Yw8IEtiy4r', '--single-transaction', '--quick', '--lock-tables=false', '_749103ee63621ec5']
      bin_name = 'mariadb-dump'
      self = <frappe.utils.backups.BackupGenerator object at 0x107ea9ae0>
  File "apps/frappe/frappe/__init__.py", line 610, in throw
    msgprint(
      msg = 'mariadb-dump not found in PATH! This is required to take a backup.'
      exc = <class 'frappe.exceptions.ExecutableNotFound'>
      title = None
      is_minimizable = False
      wide = False
      as_list = False
      primary_action = None
  File "apps/frappe/frappe/__init__.py", line 571, in msgprint
    _raise_exception()
      title = None
      as_table = False
      as_list = False
      indicator = 'red'
      alert = False
      primary_action = None
      is_minimizable = False
      wide = False
      realtime = False
      _raise_exception = <function msgprint.<locals>._raise_exception at 0x107ed57e0>
      inspect = <module 'inspect' from '/Library/Frameworks/Python.framework/Versions/3.10/lib/python3.10/inspect.py'>
      msg = 'mariadb-dump not found in PATH! This is required to take a backup.'
      out = {'message': 'mariadb-dump not found in PATH! This is required to take a backup.', 'title': 'Message', 'indicator': 'red', 'raise_exception': 1, '__frappe_exc_id': '1ff5d5556e1de7202b59d0476c1e29a5b03569a3f3aac183abf460c8'}
      raise_exception = <class 'frappe.exceptions.ExecutableNotFound'>
  File "apps/frappe/frappe/__init__.py", line 522, in _raise_exception
    raise exc
      exc = ExecutableNotFound('mariadb-dump not found in PATH! This is required to take a backup.')
      inspect = <module 'inspect' from '/Library/Frameworks/Python.framework/Versions/3.10/lib/python3.10/inspect.py'>
      msg = 'mariadb-dump not found in PATH! This is required to take a backup.'
      out = {'message': 'mariadb-dump not found in PATH! This is required to take a backup.', 'title': 'Message', 'indicator': 'red', 'raise_exception': 1, '__frappe_exc_id': '1ff5d5556e1de7202b59d0476c1e29a5b03569a3f3aac183abf460c8'}
      raise_exception = <class 'frappe.exceptions.ExecutableNotFound'>
frappe.exceptions.ExecutableNotFound: mariadb-dump not found in PATH! This is required to take a backup.
File ./frappe.test/private/backups/20250209_060712-frappe_test-database.sql.gz is recent
File ./frappe.test/private/backups/20250209_060712-frappe_test-site_config_backup.json is recent
Backup failed for Site project-management. Database or site_config.json may be corrupted
Traceback with variables (most recent call last):
  File "apps/frappe/frappe/commands/site.py", line 871, in backup
    odb = scheduled_backup(
      context = CliCtxObj(sites=['frappe.test', 'project-management'], force=False, profile=False, verbose=True)
      with_files = False
      backup_path = None
      backup_path_db = None
      backup_path_files = None
      backup_path_private_files = None
      backup_path_conf = None
      ignore_backup_conf = False
      verbose = True
      compress = False
      include = ''
      exclude = ''
      old_backup_metadata = False
      scheduled_backup = <function scheduled_backup at 0x107c9d360>
      exit_code = 1
      rollback_callback = None
      site = 'project-management'
  File "apps/frappe/frappe/utils/backups.py", line 577, in scheduled_backup
    return new_backup(
      older_than = 6
      ignore_files = True
      backup_path = None
      backup_path_db = None
      backup_path_files = None
      backup_path_private_files = None
      backup_path_conf = None
      ignore_conf = False
      include_doctypes = ''
      exclude_doctypes = ''
      compress = False
      force = True
      verbose = True
      old_backup_metadata = False
      rollback_callback = <frappe.utils.CallbackManager object at 0x107ea8790>
  File "apps/frappe/frappe/utils/backups.py", line 635, in new_backup
    odb.get_backup(older_than, ignore_files, force=force)
      older_than = 6
      ignore_files = True
      backup_path = None
      backup_path_db = None
      backup_path_files = None
      backup_path_private_files = None
      backup_path_conf = None
      ignore_conf = False
      include_doctypes = ''
      exclude_doctypes = ''
      compress = False
      force = True
      verbose = True
      old_backup_metadata = False
      rollback_callback = <frappe.utils.CallbackManager object at 0x107ea8790>
      odb = <frappe.utils.backups.BackupGenerator object at 0x107ea99c0>
  File "apps/frappe/frappe/utils/backups.py", line 191, in get_backup
    self.delete_if_step_fails(self.take_dump, self.backup_path_db)
      self = <frappe.utils.backups.BackupGenerator object at 0x107ea99c0>
      older_than = 6
      ignore_files = True
      force = True
      last_db = False
      last_file = False
      last_private_file = False
      site_config_backup_path = False
  File "apps/frappe/frappe/utils/backups.py", line 516, in delete_if_step_fails
    raise e
      self = <frappe.utils.backups.BackupGenerator object at 0x107ea99c0>
      step = <bound method BackupGenerator.take_dump of <frappe.utils.backups.BackupGenerator object at 0x107ea99c0>>
      paths = ('./frappe.test/private/backups/20250209_060004-frappe_test-database.sql.gz',)
      path = './frappe.test/private/backups/20250209_060004-frappe_test-database.sql.gz'
  File "apps/frappe/frappe/utils/backups.py", line 511, in delete_if_step_fails
    step()
      self = <frappe.utils.backups.BackupGenerator object at 0x107ea99c0>
      step = <bound method BackupGenerator.take_dump of <frappe.utils.backups.BackupGenerator object at 0x107ea99c0>>
      paths = ('./frappe.test/private/backups/20250209_060004-frappe_test-database.sql.gz',)
      path = './frappe.test/private/backups/20250209_060004-frappe_test-database.sql.gz'
  File "apps/frappe/frappe/utils/backups.py", line 453, in take_dump
    frappe.throw(
      shlex = <module 'shlex' from '/Library/Frameworks/Python.framework/Versions/3.10/lib/python3.10/shlex.py'>
      frappe = <module 'frappe' from 'apps/frappe/frappe/__init__.py'>
      get_app_branch = <function get_app_branch at 0x107ed6710>
      gzip_exc = '/usr/bin/gzip'
      database_header_content = ['begin frappe metadata', '[frappe]', 'version = 16.0.0-dev', 'branch = develop', 'end frappe metadata', '']
      generated_header = '-- begin frappe metadata\n-- [frappe]\n-- version = 16.0.0-dev\n-- branch = develop\n-- end frappe metadata\n-- \n'
      f = <_io.TextIOWrapper name='./frappe.test/private/backups/20250209_060004-frappe_test-database.sql.gz' encoding='UTF-8'>
      cmd = []
      extra = []
      get_command = <function get_command at 0x107ce2830>
      bin = None
      args = ['--user=_749103ee63621ec5', '--host=127.0.0.1', '--port=3306', '--password=64NOp3Yw8IEtiy4r', '--single-transaction', '--quick', '--lock-tables=false', '_749103ee63621ec5']
      bin_name = 'mariadb-dump'
      self = <frappe.utils.backups.BackupGenerator object at 0x107ea99c0>
  File "apps/frappe/frappe/__init__.py", line 610, in throw
    msgprint(
      msg = 'mariadb-dump not found in PATH! This is required to take a backup.'
      exc = <class 'frappe.exceptions.ExecutableNotFound'>
      title = None
      is_minimizable = False
      wide = False
      as_list = False
      primary_action = None
  File "apps/frappe/frappe/__init__.py", line 571, in msgprint
    _raise_exception()
      title = None
      as_table = False
      as_list = False
      indicator = 'red'
      alert = False
      primary_action = None
      is_minimizable = False
      wide = False
      realtime = False
      _raise_exception = <function msgprint.<locals>._raise_exception at 0x107f4fd00>
      inspect = <module 'inspect' from '/Library/Frameworks/Python.framework/Versions/3.10/lib/python3.10/inspect.py'>
      msg = 'mariadb-dump not found in PATH! This is required to take a backup.'
      out = {'message': 'mariadb-dump not found in PATH! This is required to take a backup.', 'title': 'Message', 'indicator': 'red', 'raise_exception': 1, '__frappe_exc_id': 'cb9d45f3bd687fa52800abb2b77e7bf0ce89acb915c9a1ae5a257bad'}
      raise_exception = <class 'frappe.exceptions.ExecutableNotFound'>
  File "apps/frappe/frappe/__init__.py", line 522, in _raise_exception
    raise exc
      exc = ExecutableNotFound('mariadb-dump not found in PATH! This is required to take a backup.')
      inspect = <module 'inspect' from '/Library/Frameworks/Python.framework/Versions/3.10/lib/python3.10/inspect.py'>
      msg = 'mariadb-dump not found in PATH! This is required to take a backup.'
      out = {'message': 'mariadb-dump not found in PATH! This is required to take a backup.', 'title': 'Message', 'indicator': 'red', 'raise_exception': 1, '__frappe_exc_id': 'cb9d45f3bd687fa52800abb2b77e7bf0ce89acb915c9a1ae5a257bad'}
      raise_exception = <class 'frappe.exceptions.ExecutableNotFound'>
frappe.exceptions.ExecutableNotFound: mariadb-dump not found in PATH! This is required to take a backup.
