2025-02-09 01:24:00,246 ERROR scheduler Exception in Enqueue Events for Site frappe.test
Traceback (most recent call last):
  File "/Users/effemm/Documents/frappe-/frappe-test-bench/apps/frappe/frappe/utils/scheduler.py", line 105, in enqueue_events_for_site
    if is_scheduler_inactive():
  File "/Users/effemm/Documents/frappe-/frappe-test-bench/apps/frappe/frappe/utils/scheduler.py", line 149, in is_scheduler_inactive
    if is_scheduler_disabled(verbose=verbose):
  File "/Users/effemm/Documents/frappe-/frappe-test-bench/apps/frappe/frappe/utils/scheduler.py", line 162, in is_scheduler_disabled
    frappe.db.get_single_value("System Settings", "enable_scheduler")
  File "/Users/effemm/Documents/frappe-/frappe-test-bench/apps/frappe/frappe/database/database.py", line 869, in get_single_value
    ).run()
  File "/Users/effemm/Documents/frappe-/frappe-test-bench/apps/frappe/frappe/query_builder/utils.py", line 84, in execute_query
    result = frappe.db.sql(query, params, *args, **kwargs)  # nosemgrep
  File "/Users/effemm/Documents/frappe-/frappe-test-bench/apps/frappe/frappe/database/database.py", line 215, in sql
    self.connect()
  File "/Users/effemm/Documents/frappe-/frappe-test-bench/apps/frappe/frappe/database/database.py", line 120, in connect
    self._conn: MariadbConnection | PostgresConnection = self.get_connection()
  File "/Users/effemm/Documents/frappe-/frappe-test-bench/apps/frappe/frappe/database/mariadb/database.py", line 107, in get_connection
    conn = self._get_connection()
  File "/Users/effemm/Documents/frappe-/frappe-test-bench/apps/frappe/frappe/database/mariadb/database.py", line 113, in _get_connection
    return self.create_connection()
  File "/Users/effemm/Documents/frappe-/frappe-test-bench/apps/frappe/frappe/database/mariadb/database.py", line 116, in create_connection
    return pymysql.connect(**self.get_connection_settings())
  File "/Users/effemm/Documents/frappe-/frappe-test-bench/env/lib/python3.10/site-packages/pymysql/connections.py", line 361, in __init__
    self.connect()
  File "/Users/effemm/Documents/frappe-/frappe-test-bench/env/lib/python3.10/site-packages/pymysql/connections.py", line 669, in connect
    self._request_authentication()
  File "/Users/effemm/Documents/frappe-/frappe-test-bench/env/lib/python3.10/site-packages/pymysql/connections.py", line 957, in _request_authentication
    auth_packet = self._read_packet()
  File "/Users/effemm/Documents/frappe-/frappe-test-bench/env/lib/python3.10/site-packages/pymysql/connections.py", line 775, in _read_packet
    packet.raise_for_error()
  File "/Users/effemm/Documents/frappe-/frappe-test-bench/env/lib/python3.10/site-packages/pymysql/protocol.py", line 219, in raise_for_error
    err.raise_mysql_exception(self._data)
  File "/Users/effemm/Documents/frappe-/frappe-test-bench/env/lib/python3.10/site-packages/pymysql/err.py", line 150, in raise_mysql_exception
    raise errorclass(errno, errval)
pymysql.err.OperationalError: (1045, "Access denied for user '_749103ee63621ec5'@'localhost' (using password: YES)")
2025-02-09 01:28:00,245 ERROR scheduler Exception in Enqueue Events for Site frappe.test
Traceback (most recent call last):
  File "/Users/effemm/Documents/frappe-/frappe-test-bench/apps/frappe/frappe/utils/scheduler.py", line 105, in enqueue_events_for_site
    if is_scheduler_inactive():
  File "/Users/effemm/Documents/frappe-/frappe-test-bench/apps/frappe/frappe/utils/scheduler.py", line 149, in is_scheduler_inactive
    if is_scheduler_disabled(verbose=verbose):
  File "/Users/effemm/Documents/frappe-/frappe-test-bench/apps/frappe/frappe/utils/scheduler.py", line 162, in is_scheduler_disabled
    frappe.db.get_single_value("System Settings", "enable_scheduler")
  File "/Users/effemm/Documents/frappe-/frappe-test-bench/apps/frappe/frappe/database/database.py", line 869, in get_single_value
    ).run()
  File "/Users/effemm/Documents/frappe-/frappe-test-bench/apps/frappe/frappe/query_builder/utils.py", line 84, in execute_query
    result = frappe.db.sql(query, params, *args, **kwargs)  # nosemgrep
  File "/Users/effemm/Documents/frappe-/frappe-test-bench/apps/frappe/frappe/database/database.py", line 215, in sql
    self.connect()
  File "/Users/effemm/Documents/frappe-/frappe-test-bench/apps/frappe/frappe/database/database.py", line 120, in connect
    self._conn: MariadbConnection | PostgresConnection = self.get_connection()
  File "/Users/effemm/Documents/frappe-/frappe-test-bench/apps/frappe/frappe/database/mariadb/database.py", line 107, in get_connection
    conn = self._get_connection()
  File "/Users/effemm/Documents/frappe-/frappe-test-bench/apps/frappe/frappe/database/mariadb/database.py", line 113, in _get_connection
    return self.create_connection()
  File "/Users/effemm/Documents/frappe-/frappe-test-bench/apps/frappe/frappe/database/mariadb/database.py", line 116, in create_connection
    return pymysql.connect(**self.get_connection_settings())
  File "/Users/effemm/Documents/frappe-/frappe-test-bench/env/lib/python3.10/site-packages/pymysql/connections.py", line 361, in __init__
    self.connect()
  File "/Users/effemm/Documents/frappe-/frappe-test-bench/env/lib/python3.10/site-packages/pymysql/connections.py", line 669, in connect
    self._request_authentication()
  File "/Users/effemm/Documents/frappe-/frappe-test-bench/env/lib/python3.10/site-packages/pymysql/connections.py", line 957, in _request_authentication
    auth_packet = self._read_packet()
  File "/Users/effemm/Documents/frappe-/frappe-test-bench/env/lib/python3.10/site-packages/pymysql/connections.py", line 775, in _read_packet
    packet.raise_for_error()
  File "/Users/effemm/Documents/frappe-/frappe-test-bench/env/lib/python3.10/site-packages/pymysql/protocol.py", line 219, in raise_for_error
    err.raise_mysql_exception(self._data)
  File "/Users/effemm/Documents/frappe-/frappe-test-bench/env/lib/python3.10/site-packages/pymysql/err.py", line 150, in raise_mysql_exception
    raise errorclass(errno, errval)
pymysql.err.OperationalError: (1045, "Access denied for user '_749103ee63621ec5'@'localhost' (using password: YES)")
