2025-02-09 01:38:24,663 [Job frappe.test||9d3d875a-f5d7-4622-8c43-be662796cc3e]: exception raised while executing (frappe.utils.background_jobs.execute_job)
Traceback (most recent call last):
  File "/Users/effemm/Documents/frappe-/frappe-test-bench/env/lib/python3.10/site-packages/rq/worker.py", line 1633, in perform_job
    return_value = job.perform()
  File "/Users/effemm/Documents/frappe-/frappe-test-bench/env/lib/python3.10/site-packages/rq/job.py", line 1331, in perform
    self._result = self._execute()
  File "/Users/effemm/Documents/frappe-/frappe-test-bench/env/lib/python3.10/site-packages/rq/job.py", line 1365, in _execute
    result = self.func(*self.args, **self.kwargs)
  File "/Users/effemm/Documents/frappe-/frappe-test-bench/apps/frappe/frappe/utils/background_jobs.py", line 214, in execute_job
    frappe.init(site)
  File "/Users/effemm/Documents/frappe-/frappe-test-bench/apps/frappe/frappe/__init__.py", line 309, in init
    setup_module_map(include_all_apps=not (frappe.request or frappe.job or frappe.flags.in_migrate))
  File "/Users/effemm/Documents/frappe-/frappe-test-bench/apps/frappe/frappe/__init__.py", line 1624, in setup_module_map
    for module in get_module_list(app):
  File "/Users/effemm/Documents/frappe-/frappe-test-bench/apps/frappe/frappe/__init__.py", line 1470, in get_module_list
    return get_file_items(get_app_path(app_name, "modules.txt"))
  File "/Users/effemm/Documents/frappe-/frappe-test-bench/apps/frappe/frappe/__init__.py", line 1435, in get_app_path
    return get_pymodule_path(app_name, *joins)
  File "/Users/effemm/Documents/frappe-/frappe-test-bench/apps/frappe/frappe/__init__.py", line 1465, in get_pymodule_path
    return abspath(join(dirname(get_module(scrub(modulename)).__file__ or ""), *joins))
  File "/Users/effemm/Documents/frappe-/frappe-test-bench/apps/frappe/frappe/__init__.py", line 1406, in get_module
    return importlib.import_module(modulename)
  File "/Library/Frameworks/Python.framework/Versions/3.10/lib/python3.10/importlib/__init__.py", line 126, in import_module
    return _bootstrap._gcd_import(name[level:], package, level)
  File "<frozen importlib._bootstrap>", line 1050, in _gcd_import
  File "<frozen importlib._bootstrap>", line 1027, in _find_and_load
  File "<frozen importlib._bootstrap>", line 1004, in _find_and_load_unlocked
ModuleNotFoundError: No module named 'frappe_test_app'

/Users/effemm/Documents/frappe-/frappe-test-bench/env/lib/python3.10/site-packages/pypdf/_crypt_providers/_cryptography.py:32: CryptographyDeprecationWarning: ARC4 has been moved to cryptography.hazmat.decrepit.ciphers.algorithms.ARC4 and will be removed from this module in 48.0.0.
  from cryptography.hazmat.primitives.ciphers.algorithms import AES, ARC4
2025-02-09 02:22:53,734 Could not connect to Redis instance: Connection closed by server. Retrying in 2 seconds...
2025-02-09 02:39:09,639 Could not connect to Redis instance: Connection closed by server. Retrying in 2 seconds...
2025-02-09 02:40:01,930 Could not connect to Redis instance: Connection closed by server. Retrying in 2 seconds...
2025-02-09 03:59:44,508 [Job frappe.test||e6190ced-fd71-43c3-9f6e-60245f170389]: exception raised while executing (frappe.utils.background_jobs.execute_job)
Traceback (most recent call last):
  File "/Users/effemm/Documents/frappe-/frappe-test-bench/apps/frappe/frappe/model/document.py", line 1843, in execute_action
    getattr(doc, __action)(**kwargs)
  File "/Users/effemm/Documents/frappe-/frappe-test-bench/apps/frappe/frappe/model/document.py", line 1176, in _rename
    self.name = rename_doc(doc=self, new=name, merge=merge, force=force, validate=validate_rename)
  File "/Users/effemm/Documents/frappe-/frappe-test-bench/apps/frappe/frappe/model/rename_doc.py", line 211, in rename_doc
    new_doc.run_method("after_rename", old, new, merge)
  File "/Users/effemm/Documents/frappe-/frappe-test-bench/apps/frappe/frappe/model/document.py", line 1095, in run_method
    out = Document.hook(fn)(self, *args, **kwargs)
  File "/Users/effemm/Documents/frappe-/frappe-test-bench/apps/frappe/frappe/model/document.py", line 1483, in composer
    return composed(self, method, *args, **kwargs)
  File "/Users/effemm/Documents/frappe-/frappe-test-bench/apps/frappe/frappe/model/document.py", line 1461, in runner
    add_to_return_value(self, fn(self, *args, **kwargs))
  File "/Users/effemm/Documents/frappe-/frappe-test-bench/apps/frappe/frappe/model/document.py", line 1092, in fn
    return method_object(*args, **kwargs)
  File "/Users/effemm/Documents/frappe-/frappe-test-bench/apps/frappe/frappe/core/doctype/doctype/doctype.py", line 666, in after_rename
    frappe.db.rename_table(old, new)
  File "/Users/effemm/Documents/frappe-/frappe-test-bench/apps/frappe/frappe/database/mariadb/database.py", line 261, in rename_table
    return self.sql(f"RENAME TABLE `{old_name}` TO `{new_name}`")
  File "/Users/effemm/Documents/frappe-/frappe-test-bench/apps/frappe/frappe/database/database.py", line 238, in sql
    self._cursor.execute(query, values)
  File "/Users/effemm/Documents/frappe-/frappe-test-bench/env/lib/python3.10/site-packages/pymysql/cursors.py", line 153, in execute
    result = self._query(query)
  File "/Users/effemm/Documents/frappe-/frappe-test-bench/env/lib/python3.10/site-packages/pymysql/cursors.py", line 322, in _query
    conn.query(q)
  File "/Users/effemm/Documents/frappe-/frappe-test-bench/env/lib/python3.10/site-packages/pymysql/connections.py", line 563, in query
    self._affected_rows = self._read_query_result(unbuffered=unbuffered)
  File "/Users/effemm/Documents/frappe-/frappe-test-bench/env/lib/python3.10/site-packages/pymysql/connections.py", line 825, in _read_query_result
    result.read()
  File "/Users/effemm/Documents/frappe-/frappe-test-bench/env/lib/python3.10/site-packages/pymysql/connections.py", line 1199, in read
    first_packet = self.connection._read_packet()
  File "/Users/effemm/Documents/frappe-/frappe-test-bench/env/lib/python3.10/site-packages/pymysql/connections.py", line 775, in _read_packet
    packet.raise_for_error()
  File "/Users/effemm/Documents/frappe-/frappe-test-bench/env/lib/python3.10/site-packages/pymysql/protocol.py", line 219, in raise_for_error
    err.raise_mysql_exception(self._data)
  File "/Users/effemm/Documents/frappe-/frappe-test-bench/env/lib/python3.10/site-packages/pymysql/err.py", line 150, in raise_mysql_exception
    raise errorclass(errno, errval)
pymysql.err.OperationalError: (1050, "Table 'tabTask' already exists")

During handling of the above exception, another exception occurred:

Traceback (most recent call last):
  File "/Users/effemm/Documents/frappe-/frappe-test-bench/env/lib/python3.10/site-packages/rq/worker.py", line 1633, in perform_job
    return_value = job.perform()
  File "/Users/effemm/Documents/frappe-/frappe-test-bench/env/lib/python3.10/site-packages/rq/job.py", line 1331, in perform
    self._result = self._execute()
  File "/Users/effemm/Documents/frappe-/frappe-test-bench/env/lib/python3.10/site-packages/rq/job.py", line 1365, in _execute
    result = self.func(*self.args, **self.kwargs)
  File "/Users/effemm/Documents/frappe-/frappe-test-bench/apps/frappe/frappe/utils/background_jobs.py", line 244, in execute_job
    retval = method(**kwargs)
  File "/Users/effemm/Documents/frappe-/frappe-test-bench/apps/frappe/frappe/model/document.py", line 1853, in execute_action
    doc.add_comment("Comment", _("Action Failed") + "<br><br>" + msg)
  File "/Users/effemm/Documents/frappe-/frappe-test-bench/apps/frappe/frappe/utils/typing_validations.py", line 32, in wrapper
    return func(*args, **kwargs)
  File "/Users/effemm/Documents/frappe-/frappe-test-bench/apps/frappe/frappe/model/document.py", line 1573, in add_comment
    return frappe.get_doc(
  File "/Users/effemm/Documents/frappe-/frappe-test-bench/apps/frappe/frappe/model/document.py", line 123, in wrapper
    return func(self, *args, **kwargs)
  File "/Users/effemm/Documents/frappe-/frappe-test-bench/apps/frappe/frappe/model/document.py", line 391, in insert
    self._validate_links()
  File "/Users/effemm/Documents/frappe-/frappe-test-bench/apps/frappe/frappe/model/document.py", line 1063, in _validate_links
    frappe.throw(_("Could not find {0}").format(msg), frappe.LinkValidationError)
  File "/Users/effemm/Documents/frappe-/frappe-test-bench/apps/frappe/frappe/__init__.py", line 610, in throw
    msgprint(
  File "/Users/effemm/Documents/frappe-/frappe-test-bench/apps/frappe/frappe/__init__.py", line 571, in msgprint
    _raise_exception()
  File "/Users/effemm/Documents/frappe-/frappe-test-bench/apps/frappe/frappe/__init__.py", line 522, in _raise_exception
    raise exc
frappe.exceptions.LinkValidationError: Could not find Reference Name: Goals

2025-02-09 04:12:02,070 Could not connect to Redis instance: Connection closed by server. Retrying in 2 seconds...
2025-02-09 04:23:43,006 Could not connect to Redis instance: Connection closed by server. Retrying in 2 seconds...
2025-02-09 04:37:27,596 Could not connect to Redis instance: Connection closed by server. Retrying in 2 seconds...
2025-02-09 05:12:53,872 Could not connect to Redis instance: Connection closed by server. Retrying in 2 seconds...
2025-02-09 05:21:00,940 Could not connect to Redis instance: Connection closed by server. Retrying in 2 seconds...
2025-02-09 05:24:20,507 Could not connect to Redis instance: Connection closed by server. Retrying in 2 seconds...
2025-02-09 05:29:54,931 Could not connect to Redis instance: Connection closed by server. Retrying in 2 seconds...
/Users/effemm/Documents/frappe-/frappe-test-bench/env/lib/python3.10/site-packages/pypdf/_crypt_providers/_cryptography.py:32: CryptographyDeprecationWarning: ARC4 has been moved to cryptography.hazmat.decrepit.ciphers.algorithms.ARC4 and will be removed from this module in 48.0.0.
  from cryptography.hazmat.primitives.ciphers.algorithms import AES, ARC4
/Users/effemm/Documents/frappe-/frappe-test-bench/env/lib/python3.10/site-packages/pypdf/_crypt_providers/_cryptography.py:32: CryptographyDeprecationWarning: ARC4 has been moved to cryptography.hazmat.decrepit.ciphers.algorithms.ARC4 and will be removed from this module in 48.0.0.
  from cryptography.hazmat.primitives.ciphers.algorithms import AES, ARC4
/Users/effemm/Documents/frappe-/frappe-test-bench/env/lib/python3.10/site-packages/pypdf/_crypt_providers/_cryptography.py:32: CryptographyDeprecationWarning: ARC4 has been moved to cryptography.hazmat.decrepit.ciphers.algorithms.ARC4 and will be removed from this module in 48.0.0.
  from cryptography.hazmat.primitives.ciphers.algorithms import AES, ARC4
/Users/effemm/Documents/frappe-/frappe-test-bench/env/lib/python3.10/site-packages/pypdf/_crypt_providers/_cryptography.py:32: CryptographyDeprecationWarning: ARC4 has been moved to cryptography.hazmat.decrepit.ciphers.algorithms.ARC4 and will be removed from this module in 48.0.0.
  from cryptography.hazmat.primitives.ciphers.algorithms import AES, ARC4
/Users/effemm/Documents/frappe-/frappe-test-bench/env/lib/python3.10/site-packages/pypdf/_crypt_providers/_cryptography.py:32: CryptographyDeprecationWarning: ARC4 has been moved to cryptography.hazmat.decrepit.ciphers.algorithms.ARC4 and will be removed from this module in 48.0.0.
  from cryptography.hazmat.primitives.ciphers.algorithms import AES, ARC4
/Users/effemm/Documents/frappe-/frappe-test-bench/env/lib/python3.10/site-packages/pypdf/_crypt_providers/_cryptography.py:32: CryptographyDeprecationWarning: ARC4 has been moved to cryptography.hazmat.decrepit.ciphers.algorithms.ARC4 and will be removed from this module in 48.0.0.
  from cryptography.hazmat.primitives.ciphers.algorithms import AES, ARC4
/Users/effemm/Documents/frappe-/frappe-test-bench/env/lib/python3.10/site-packages/pypdf/_crypt_providers/_cryptography.py:32: CryptographyDeprecationWarning: ARC4 has been moved to cryptography.hazmat.decrepit.ciphers.algorithms.ARC4 and will be removed from this module in 48.0.0.
  from cryptography.hazmat.primitives.ciphers.algorithms import AES, ARC4
2025-02-09 06:49:05,891 Could not connect to Redis instance: Connection closed by server. Retrying in 2 seconds...
